Workbook
Name BaseRates: RateTables!$A$3:$D$10
Name AgeBands: RateTables!$E$12:$F$18
Name RoofBands: RateTables!$H$12:$I$16
Name AOIBands: RateTables!$K$12:$L$18
Name DedBands: RateTables!$A$31:$B$36
Name ClaimsTable: RateTables!$E$31:$F$34
Name HurrDedTable: RateTables!$H$31:$I$33
Name FeeTable: RateTables!$N$31:$O$32
Name CreditPcts: RateTables!$B$40:$F$40
Name CreditCap: RateTables!$B$42
Name MinPremium: RateTables!$B$43
Name AssessRate: RateTables!$B$44
Name HurrCapPct: RateTables!$B$45

Sheet Policies
A1: policy_id | B1: zone | C1: construction | D1: protection_class | E1: year_built | F1: roof_age | G1: coverage_a | H1: deductible | I1: hurr_ded_pct | J1: alarm | K1: wind_mit | L1: claims_3yr | M1: effective_date | N1: term_months
A2: HO-000001 | B2: T08 | C2: FireResistive | D2: 9 | E2: 1958 | F2: 26 | G2: 1282793 | H2: 0 | I2: 0.03 | J2: Y | K2: fortified | L2: 0 | M2: 46458 | N2: 12
A3: HO-000002 | B3: T01 | C3: Frame | D3: 10 | E3: 1979 | F3: 14 | G3: 391000 | H3: 499 | I3: 0.1 | J3: y | K3: fortified | L3: 1 | M3: 46860 | N3: 6
A4: HO-000003 | B4: T05 | C4: FireResistive | D4: 7 | E4: 1980 | F4: 5 | G4: 702000 | H4: 500 | I4: 0.02 | J4: Y | L4: 4 | M4: 46708 | N4: 6
A5: HO-000004 | B5: T04 | C5: MasonryVeneer | D5: 8 | E5: 1984 | F5: 15 | G5: 1118000 | H5: 999 | I5: 0.05 | J5: y | K5: None | L5: 3 | M5: 46391 | N5: 12
A6: HO-000005 | B6: T03 | C6: FireResistive | D6: 8 | E6: 1933 | F6: 19 | G6: 1145264 | H6: 1000 | I6: 0.02 | J6: y | K6: Basic | L6: 3 | M6: 46486 | N6: 12
A7: HO-000006 | B7: T01 | C7: FireResistive | D7: 10 | E7: 1994 | F7: 28 | G7: 270000 | H7: 2499 | J7: Y | K7: None | L7: 4 | M7: 46117 | N7: 12
A8: HO-000007 | B8: T06 | C8: Masonry | D8: 1 | E8: 1965 | F8: 20 | G8: 1304359 | H8: 2500 | I8: 0.03 | J8: N | L8: 0 | M8: 46707 | N8: 12
A9: HO-000008 | B9: T07 | C9: Masonry | D9: 3 | E9: 2025 | F9: 24 | G9: 741737 | H9: 4999 | I9: 0.02 | J9: Y | K9: Basic | L9: 2 | M9: 46109 | N9: 12
A10: HO-000009 | B10: T07 | C10: Frame | D10: 1 | E10: 1969 | F10: 19 | G10: 823000 | H10: 5000 | I10: 0.1 | K10: Fortified | L10: 3 | M10: 46131 | N10: 12
A11: HO-000010 | B11: T08 | C11: FireResistive | D11: 10 | E11: 2004 | F11: 24 | G11: 449000 | H11: 9999 | I11: 0.03 | L11: 0 | M11: 46147 | N11: 12
A12: HO-000011 | B12: T07 | C12: Frame | D12: 4 | E12: 2007 | F12: 28 | G12: 455000 | H12: 10000 | I12: 0.02 | J12: y | K12: None | L12: 0 | M12: 46583 | N12: 12
A13: HO-000012 | B13: T03 | C13: Masonry | D13: 3 | E13: 1974 | F13: 7 | G13: 1217804 | H13: 10001 | I13: 0.1 | K13: Basic | L13: 1 | M13: 46827 | N13: 12
A14: HO-000013 | B14: T08 | C14: FireResistive | D14: 7 | E14: 1961 | F14: 13 | G14: 783229 | H14: 50000 | J14: Y | K14: fortified | L14: 1 | M14: 46292 | N14: 12
A15: HO-000014 | B15: T04 | C15: Masonry | D15: 1 | E15: 1936 | F15: 27 | G15: 100000 | H15: 10000 | I15: 0.03 | J15: N | K15: None | L15: 1 | M15: 46891 | N15: 12
A16: HO-000015 | B16: T04 | C16: Frame | D16: 10 | E16: 2016 | F16: 7 | G16: 149999 | H16: 7500 | I16: 0.05 | J16: Y | K16: Fortified | L16: 4 | M16: 46383 | N16: 12
A17: HO-000016 | B17: T03 | C17: Masonry | D17: 4 | E17: 1990 | F17: 8 | G17: 350000 | H17: 1000 | I17: 0.02 | J17: N | K17: None | L17: 0 | M17: 46143 | N17: 12
A18: HO-000017 | B18: T05 | C18: Frame | D18: 7 | E18: 1946 | F18: 2 | G18: 150000 | H18: 1000 | J18: Y | K18: Fortified | L18: 1 | M18: 46126 | N18: 12
A19: HO-000018 | B19: T06 | C19: Masonry | D19: 5 | E19: 1957 | F19: 1 | G19: 249999 | H19: 10000 | J19: Y | K19: None | L19: 0 | M19: 46321 | N19: 12
A20: HO-000019 | B20: T02 | C20: Frame | D20: 9 | E20: 1998 | F20: 28 | G20: 250000 | H20: 7500 | I20: 0.03 | J20: Y | L20: 1 | M20: 46340 | N20: 12
A21: HO-000020 | B21: T08 | C21: FireResistive | D21: 2 | E21: 2012 | F21: 10 | G21: 399999 | H21: 10000 | I21: 0.05 | K21: None | L21: 2 | M21: 46631 | N21: 12
A22: HO-000021 | B22: T06 | C22: MasonryVeneer | D22: 2 | E22: 1963 | F22: 23 | G22: 400000 | H22: 1500 | I22: 0.05 | J22: N | K22: fortified | M22: 46311 | N22: 12
A23: HO-000022 | B23: T02 | C23: Frame | D23: 1 | E23: 1941 | F23: 15 | G23: 599999 | H23: 500 | I23: 0.1 | J23: Y | K23: Basic | L23: 1 | M23: 46189 | N23: 6
A24: HO-000023 | B24: T07 | C24: Masonry | D24: 7 | E24: 2009 | F24: 6 | G24: 600000 | H24: 25000 | I24: 0.03 | J24: Y | L24: 1 | M24: 46416 | N24: 12
A25: HO-000024 | B25: T01 | C25: Frame | D25: 5 | E25: 1994 | F25: 14 | G25: 999999 | H25: 1000 | I25: 0.03 | J25: Y | K25: Basic | L25: 4 | M25: 46256 | N25: 12
A26: HO-000025 | B26: T05 | C26: MasonryVeneer | D26: 9 | E26: 2021 | F26: 22 | G26: 1000000 | H26: 25000 | I26: 0.02 | J26: y | K26: None | L26: 0 | M26: 46688 | N26: 12
A27: HO-000026 | B27: T07 | C27: MasonryVeneer | D27: 4 | E27: 1996 | F27: 25 | G27: 1000001 | H27: 5000 | I27: 0.05 | J27: y | L27: 4 | M27: 46786 | N27: 6
A28: HO-000027 | B28: T05 | C28: Masonry | D28: 3 | E28: 2005 | F28: 12 | G28: 1999999 | H28: 5000 | I28: 0.03 | J28: y | K28: None | L28: 0 | M28: 46830 | N28: 12
A29: HO-000028 | B29: T06 | C29: MasonryVeneer | D29: 3 | E29: 2016 | F29: 22 | G29: 2000000 | H29: 7500 | I29: 0.05 | J29: Y | K29: None | L29: 2 | M29: 46329 | N29: 6
A30: HO-000029 | B30: T03 | C30: Frame | D30: 2 | E30: 2027 | F30: 22 | G30: 799630 | H30: 2500 | J30: Y | K30: Basic | L30: 0 | M30: 46447 | N30: 12
A31: HO-000030 | B31: T05 | C31: Masonry | D31: 7 | E31: 2023 | F31: 14 | G31: 741881 | H31: 1000 | I31: 0.05 | J31: Y | K31: Fortified | L31: 0 | M31: 46539 | N31: 12
A32: HO-000031 | B32: T05 | C32: MasonryVeneer | D32: 3 | E32: 2025 | F32: 5 | G32: 119815 | H32: 10000 | I32: 0.05 | J32: Y | K32: Basic | L32: 4 | M32: 46447 | N32: 12
A33: HO-000032 | B33: T06 | C33: Masonry | D33: 3 | E33: 2024 | F33: 27 | G33: 338000 | H33: 5000 | K33: Fortified | L33: 0 | M33: 46447 | N33: 12
A34: HO-000033 | B34: T04 | C34: Masonry | D34: 2 | E34: 2023 | F34: 14 | G34: 253367 | H34: 2500 | I34: 0.03 | K34: None | L34: 1 | M34: 46447 | N34: 6
A35: HO-000034 | B35: T02 | C35: Masonry | D35: 6 | E35: 2022 | F35: 25 | G35: 1327494 | H35: 1000 | J35: Y | L35: 1 | M35: 46447 | N35: 12
A36: HO-000035 | B36: T04 | C36: Masonry | D36: 6 | E36: 2021 | F36: 15 | G36: 795651 | H36: 25000 | I36: 0.1 | J36: y | K36: Fortified | L36: 0 | M36: 46447 | N36: 12
A37: HO-000036 | B37: T08 | C37: Masonry | D37: 6 | E37: 2018 | F37: 24 | G37: 959202 | H37: 2500 | I37: 0.02 | J37: y | K37: fortified | L37: 0 | M37: 46447 | N37: 6
A38: HO-000037 | B38: T06 | C38: Frame | D38: 6 | E38: 2017 | F38: 25 | G38: 1010000 | H38: 1500 | I38: 0.05 | J38: N | K38: Fortified | L38: 0 | M38: 46447 | N38: 12
A39: HO-000038 | B39: T05 | C39: FireResistive | D39: 7 | E39: 2008 | G39: 790319 | H39: 5000 | J39: y | K39: fortified | L39: 4 | M39: 46447 | N39: 12
A40: HO-000039 | B40: T06 | C40: MasonryVeneer | D40: 1 | E40: 2007 | F40: 22 | G40: 122052 | H40: 1500 | I40: 0.05 | J40: N | K40: Fortified | L40: 2 | M40: 46447 | N40: 6
...

Sheet RateTables
A1: FICTIONAL — all names, rates and rules invented for a software demonstration | Example Mutual Insurance Co. (FICTIONAL) HO-3 rate tables
A2: Zone | B2: AOP rate/1000 | C2: Hurr rate/1000 | D2: Tax rate
A3: T01 | B3: 3.125 | C3: 0.45 | D3: 0.0175
A4: T02 | B4: 3.375 | C4: 0.875 | D4: 0.0175
A5: T03 | B5: 3.64 | C5: 1.25 | D5: 0.02
A6: T04 | B6: 2.98 | C6: 2.125 | D6: 0.02
A7: T05 | B7: 4.115 | C7: 3.375 | D7: 0.0225
A8: T06 | B8: 3.505 | C8: 4.625 | D8: 0.0225
A9: T07 | B9: 4.25 | C9: 5.875 | D9: 0.025
A10: T08 | B10: 2.875 | C10: 6.5 | D10: 0.025
E11: Home age >= | H11: Roof age >= | K11: Coverage A >=
A12: Construction | B12: AOP factor | C12: Hurr factor | E12: 0 | F12: 0.9 | H12: 0 | I12: 0.95 | K12: 0 | L12: 0.8
A13: Frame | B13: 1 | C13: 1 | E13: 5 | F13: 0.95 | H13: 6 | I13: 1 | K13: 150000 | L13: 0.9
A14: Masonry | B14: 0.88 | C14: 0.8 | E14: 10 | F14: 1 | H14: 11 | I14: 1.1 | K14: 250000 | L14: 1
A15: MasonryVeneer | B15: 0.94 | C15: 0.9 | E15: 20 | F15: 1.08 | H15: 16 | I15: 1.25 | K15: 400000 | L15: 1.12
A16: FireResistive | B16: 0.8 | C16: 0.7 | E16: 30 | F16: 1.15 | H16: 21 | I16: 1.45 | K16: 600000 | L16: 1.25
E17: 50 | F17: 1.25 | K17: 1000000 | L17: 1.4
A18: PC | B18: Frame | C18: NonFrame | E18: 75 | F18: 1.35 | K18: 2000000 | L18: 1.55
A19: 1 | B19: 0.85 | C19: 0.82
A20: 2 | B20: 0.87 | C20: 0.84
A21: 3 | B21: 0.9 | C21: 0.86
A22: 4 | B22: 0.93 | C22: 0.89
A23: 5 | B23: 0.97 | C23: 0.93
A24: 6 | B24: 1 | C24: 0.96
A25: 7 | B25: 1.06 | C25: 1.01
A26: 8 | B26: 1.15 | C26: 1.09
A27: 9 | B27: 1.4 | C27: 1.3
A28: 10 | B28: 1.75 | C28: 1.6
A30: Deductible >= | E30: Claims | H30: Hurr ded % | K30: Wind mitigation | N30: Term months
A31: 0 | B31: 1.1 | E31: 0 | F31: 1 | H31: 0.02 | I31: 1 | K31: None | L31: 1 | N31: 6 | O31: 15
A32: 500 | B32: 1 | E32: 1 | F32: 1.1 | H32: 0.05 | I32: 0.85 | K32: Basic | L32: 0.85 | N32: 12 | O32: 25
A33: 1000 | B33: 0.92 | E33: 2 | F33: 1.25 | H33: 0.1 | I33: 0.72 | K33: Fortified | L33: 0.65
A34: 2500 | B34: 0.82 | E34: 3 | F34: 1.5
A35: 5000 | B35: 0.74
A36: 10000 | B36: 0.66
A39: Credit | B39: Alarm | C39: ClaimsFree | D39: NewHome | E39: MitBasic | F39: MitFortified
A40: Credit % | B40: 0.05 | C40: 0.1 | D40: 0.08 | E40: 0.04 | F40: 0.1
A42: CreditCap | B42: 0.25
A43: MinPremium | B43: 350
A44: AssessRate | B44: 0.013
...

Sheet Calc
A1: policy_id | B1: home_age | C1: roof_age_used | D1: aoi_units | E1: base_rate | F1: hurr_rate | G1: tax_rate | H1: base_premium | I1: constr_factor | J1: constr_hurr_factor | K1: pc_factor | L1: age_factor | M1: roof_factor | N1: aoi_factor | O1: ded_factor | P1: claims_factor | Q1: aop_premium | R1: alarm_flag | S1: claims_free_flag | T1: new_home_flag | U1: mit_basic_flag | V1: mit_fort_flag | W1: credit_raw | X1: credit_pct | Y1: aop_net | Z1: hurr_pct_used | AA1: hurr_ded_factor | AB1: wind_mit_factor | AC1: hurr_premium | AD1: hurr_capped | AE1: subtotal | AF1: exp_date | AG1: term_factor | AH1: term_premium | AI1: min_applied | AJ1: premium_rounded | AK1: policy_fee | AL1: assessment | AM1: tax | AN1: total_due | AO1: refer_flag | AP1: rate_per_1000 | AQ1: rate_class
A2: =Policies!A2 | B2: =IFERROR(DATEDIF(DATE(Policies!E2,1,1),Policies!M2,"y"),0) | C2: =Policies!F2*1 | D2: =Policies!G2/1000 | E2: =VLOOKUP(Policies!B2,BaseRates,2,FALSE) | F2: =VLOOKUP(Policies!B2,BaseRates,3,FALSE) | G2: =VLOOKUP(Policies!B2,BaseRates,4,FALSE) | H2: =ROUND(E2*D2,2) | I2: =INDEX(RateTables!$B$13:$B$16,MATCH(Policies!C2,RateTables!$A$13:$A$16,0)) | J2: =INDEX(RateTables!$C$13:$C$16,MATCH(Policies!C2,RateTables!$A$13:$A$16,0)) | K2: =INDEX(RateTables!$B$19:$C$28,MATCH(Policies!D2,RateTables!$A$19:$A$28,0),IF(Policies!C2="Frame",1,2)) | L2: =VLOOKUP(B2,AgeBands,2,TRUE) | M2: =VLOOKUP(C2,RoofBands,2,TRUE) | N2: =VLOOKUP(Policies!G2,AOIBands,2,TRUE) | O2: =VLOOKUP(Policies!H2,RateTables!$A$31:$B$35,2,TRUE) | P2: =VLOOKUP(MIN(Policies!L2,3),ClaimsTable,2,FALSE) | Q2: =ROUND(H2*I2*K2*L2*M2*N2*O2*P2,2) | R2: =IF(Policies!J2="Y",1,0) | S2: =IF(AND(Policies!L2=0,B2>=3),1,0) | T2: =IF(B2<=5,1,0) | U2: =IF(Policies!K2="Basic",1,0) | V2: =IF(Policies!K2="Fortified",1,0) | W2: =SUMPRODUCT(R2:V2,CreditPcts) | X2: =MIN(W2,CreditCap) | Y2: =ROUND(Q2*(1-X2),2) | Z2: =IF(Policies!I2="",0.02,Policies!I2) | AA2: =IFERROR(VLOOKUP(Z2,HurrDedTable,2,FALSE),1) | AB2: =IFERROR(INDEX(RateTables!$L$31:$L$33,MATCH(Policies!K2,RateTables!$K$31:$K$33,0)),1) | AC2: =ROUND(F2*D2*J2*AA2*AB2,2) | AD2: =MIN(AC2,Policies!G2*HurrCapPct) | AE2: =Y2+AD2 | AF2: =EDATE(Policies!M2,Policies!N2) | AG2: =ROUND(YEARFRAC(Policies!M2,AF2,3),4) | AH2: =ROUND(AE2*AG2,2) | AI2: =MAX(AH2,MinPremium) | AJ2: =ROUNDUP(AI2,0) | AK2: =VLOOKUP(Policies!N2,FeeTable,2,FALSE) | AL2: =ROUND(AJ2*AssessRate,2) | AM2: =ROUND((AJ2+AK2)*G2,2) | AN2: =AJ2+AK2+AL2+AM2 | AO2: =IF(OR(Policies!G2>1000000,C2>20,Policies!L2>=3),"REFER","OK") | AP2: =ROUND(AH2/D2,3) | AQ2: =Policies!B2&"-"&LEFT(Policies!C2,1)&TEXT(Policies!D2,"00")
A3: =Policies!A3 | B3: =IFERROR(DATEDIF(DATE(Policies!E3,1,1),Policies!M3,"y"),0) | C3: =Policies!F3*1 | D3: =Policies!G3/1000 | E3: =VLOOKUP(Policies!B3,BaseRates,2,FALSE) | F3: =VLOOKUP(Policies!B3,BaseRates,3,FALSE) | G3: =VLOOKUP(Policies!B3,BaseRates,4,FALSE) | H3: =ROUND(E3*D3,2) | I3: =INDEX(RateTables!$B$13:$B$16,MATCH(Policies!C3,RateTables!$A$13:$A$16,0)) | J3: =INDEX(RateTables!$C$13:$C$16,MATCH(Policies!C3,RateTables!$A$13:$A$16,0)) | K3: =INDEX(RateTables!$B$19:$C$28,MATCH(Policies!D3,RateTables!$A$19:$A$28,0),IF(Policies!C3="Frame",1,2)) | L3: =VLOOKUP(B3,AgeBands,2,TRUE) | M3: =VLOOKUP(C3,RoofBands,2,TRUE) | N3: =VLOOKUP(Policies!G3,AOIBands,2,TRUE) | O3: =VLOOKUP(Policies!H3,RateTables!$A$31:$B$35,2,TRUE) | P3: =VLOOKUP(MIN(Policies!L3,3),ClaimsTable,2,FALSE) | Q3: =ROUND(H3*I3*K3*L3*M3*N3*O3*P3,2) | R3: =IF(Policies!J3="Y",1,0) | S3: =IF(AND(Policies!L3=0,B3>=3),1,0) | T3: =IF(B3<=5,1,0) | U3: =IF(Policies!K3="Basic",1,0) | V3: =IF(Policies!K3="Fortified",1,0) | W3: =SUMPRODUCT(R3:V3,CreditPcts) | X3: =MIN(W3,CreditCap) | Y3: =ROUND(Q3*(1-X3),2) | Z3: =IF(Policies!I3="",0.02,Policies!I3) | AA3: =IFERROR(VLOOKUP(Z3,HurrDedTable,2,FALSE),1) | AB3: =IFERROR(INDEX(RateTables!$L$31:$L$33,MATCH(Policies!K3,RateTables!$K$31:$K$33,0)),1) | AC3: =ROUND(F3*D3*J3*AA3*AB3,2) | AD3: =MIN(AC3,Policies!G3*HurrCapPct) | AE3: =Y3+AD3 | AF3: =EDATE(Policies!M3,Policies!N3) | AG3: =ROUND(YEARFRAC(Policies!M3,AF3,3),4) | AH3: =ROUND(AE3*AG3,2) | AI3: =MAX(AH3,MinPremium) | AJ3: =ROUNDUP(AI3,0) | AK3: =VLOOKUP(Policies!N3,FeeTable,2,FALSE) | AL3: =ROUND(AJ3*AssessRate,2) | AM3: =ROUND((AJ3+AK3)*G3,2) | AN3: =AJ3+AK3+AL3+AM3 | AO3: =IF(OR(Policies!G3>1000000,C3>20,Policies!L3>=3),"REFER","OK") | AP3: =ROUND(AH3/D3,3) | AQ3: =Policies!B3&"-"&LEFT(Policies!C3,1)&TEXT(Policies!D3,"00")
A4: =Policies!A4 | B4: =IFERROR(DATEDIF(DATE(Policies!E4,1,1),Policies!M4,"y"),0) | C4: =Policies!F4*1 | D4: =Policies!G4/1000 | E4: =VLOOKUP(Policies!B4,BaseRates,2,FALSE) | F4: =VLOOKUP(Policies!B4,BaseRates,3,FALSE) | G4: =VLOOKUP(Policies!B4,BaseRates,4,FALSE) | H4: =ROUND(E4*D4,2) | I4: =INDEX(RateTables!$B$13:$B$16,MATCH(Policies!C4,RateTables!$A$13:$A$16,0)) | J4: =INDEX(RateTables!$C$13:$C$16,MATCH(Policies!C4,RateTables!$A$13:$A$16,0)) | K4: =INDEX(RateTables!$B$19:$C$28,MATCH(Policies!D4,RateTables!$A$19:$A$28,0),IF(Policies!C4="Frame",1,2)) | L4: =VLOOKUP(B4,AgeBands,2,TRUE) | M4: =VLOOKUP(C4,RoofBands,2,TRUE) | N4: =VLOOKUP(Policies!G4,AOIBands,2,TRUE) | O4: =VLOOKUP(Policies!H4,RateTables!$A$31:$B$35,2,TRUE) | P4: =VLOOKUP(MIN(Policies!L4,3),ClaimsTable,2,FALSE) | Q4: =ROUND(H4*I4*K4*L4*M4*N4*O4*P4,2) | R4: =IF(Policies!J4="Y",1,0) | S4: =IF(AND(Policies!L4=0,B4>=3),1,0) | T4: =IF(B4<=5,1,0) | U4: =IF(Policies!K4="Basic",1,0) | V4: =IF(Policies!K4="Fortified",1,0) | W4: =SUMPRODUCT(R4:V4,CreditPcts) | X4: =MIN(W4,CreditCap) | Y4: =ROUND(Q4*(1-X4),2) | Z4: =IF(Policies!I4="",0.02,Policies!I4) | AA4: =IFERROR(VLOOKUP(Z4,HurrDedTable,2,FALSE),1) | AB4: =IFERROR(INDEX(RateTables!$L$31:$L$33,MATCH(Policies!K4,RateTables!$K$31:$K$33,0)),1) | AC4: =ROUND(F4*D4*J4*AA4*AB4,2) | AD4: =MIN(AC4,Policies!G4*HurrCapPct) | AE4: =Y4+AD4 | AF4: =EDATE(Policies!M4,Policies!N4) | AG4: =ROUND(YEARFRAC(Policies!M4,AF4,3),4) | AH4: =ROUND(AE4*AG4,2) | AI4: =MAX(AH4,MinPremium) | AJ4: =ROUNDUP(AI4,0) | AK4: =VLOOKUP(Policies!N4,FeeTable,2,FALSE) | AL4: =ROUND(AJ4*AssessRate,2) | AM4: =ROUND((AJ4+AK4)*G4,2) | AN4: =AJ4+AK4+AL4+AM4 | AO4: =IF(OR(Policies!G4>1000000,C4>20,Policies!L4>=3),"REFER","OK") | AP4: =ROUND(AH4/D4,3) | AQ4: =Policies!B4&"-"&LEFT(Policies!C4,1)&TEXT(Policies!D4,"00")
A5: =Policies!A5 | B5: =IFERROR(DATEDIF(DATE(Policies!E5,1,1),Policies!M5,"y"),0) | C5: =Policies!F5*1 | D5: =Policies!G5/1000 | E5: =VLOOKUP(Policies!B5,BaseRates,2,FALSE) | F5: =VLOOKUP(Policies!B5,BaseRates,3,FALSE) | G5: =VLOOKUP(Policies!B5,BaseRates,4,FALSE) | H5: =ROUND(E5*D5,2) | I5: =INDEX(RateTables!$B$13:$B$16,MATCH(Policies!C5,RateTables!$A$13:$A$16,0)) | J5: =INDEX(RateTables!$C$13:$C$16,MATCH(Policies!C5,RateTables!$A$13:$A$16,0)) | K5: =INDEX(RateTables!$B$19:$C$28,MATCH(Policies!D5,RateTables!$A$19:$A$28,0),IF(Policies!C5="Frame",1,2)) | L5: =VLOOKUP(B5,AgeBands,2,TRUE) | M5: =VLOOKUP(C5,RoofBands,2,TRUE) | N5: =VLOOKUP(Policies!G5,AOIBands,2,TRUE) | O5: =VLOOKUP(Policies!H5,RateTables!$A$31:$B$35,2,TRUE) | P5: =VLOOKUP(MIN(Policies!L5,3),ClaimsTable,2,FALSE) | Q5: =ROUND(H5*I5*K5*L5*M5*N5*O5*P5,2) | R5: =IF(Policies!J5="Y",1,0) | S5: =IF(AND(Policies!L5=0,B5>=3),1,0) | T5: =IF(B5<=5,1,0) | U5: =IF(Policies!K5="Basic",1,0) | V5: =IF(Policies!K5="Fortified",1,0) | W5: =SUMPRODUCT(R5:V5,CreditPcts) | X5: =MIN(W5,CreditCap) | Y5: =ROUND(Q5*(1-X5),2) | Z5: =IF(Policies!I5="",0.02,Policies!I5) | AA5: =IFERROR(VLOOKUP(Z5,HurrDedTable,2,FALSE),1) | AB5: =IFERROR(INDEX(RateTables!$L$31:$L$33,MATCH(Policies!K5,RateTables!$K$31:$K$33,0)),1) | AC5: =ROUND(F5*D5*J5*AA5*AB5,2) | AD5: =MIN(AC5,Policies!G5*HurrCapPct) | AE5: =Y5+AD5 | AF5: =EDATE(Policies!M5,Policies!N5) | AG5: =ROUND(YEARFRAC(Policies!M5,AF5,3),4) | AH5: =ROUND(AE5*AG5,2) | AI5: =MAX(AH5,MinPremium) | AJ5: =ROUNDUP(AI5,0) | AK5: =VLOOKUP(Policies!N5,FeeTable,2,FALSE) | AL5: =ROUND(AJ5*AssessRate,2) | AM5: =ROUND((AJ5+AK5)*G5,2) | AN5: =AJ5+AK5+AL5+AM5 | AO5: =IF(OR(Policies!G5>1000000,C5>20,Policies!L5>=3),"REFER","OK") | AP5: =ROUND(AH5/D5,3) | AQ5: =Policies!B5&"-"&LEFT(Policies!C5,1)&TEXT(Policies!D5,"00")
A6: =Policies!A6 | B6: =IFERROR(DATEDIF(DATE(Policies!E6,1,1),Policies!M6,"y"),0) | C6: =Policies!F6*1 | D6: =Policies!G6/1000 | E6: =VLOOKUP(Policies!B6,BaseRates,2,FALSE) | F6: =VLOOKUP(Policies!B6,BaseRates,3,FALSE) | G6: =VLOOKUP(Policies!B6,BaseRates,4,FALSE) | H6: =ROUND(E6*D6,2) | I6: =INDEX(RateTables!$B$13:$B$16,MATCH(Policies!C6,RateTables!$A$13:$A$16,0)) | J6: =INDEX(RateTables!$C$13:$C$16,MATCH(Policies!C6,RateTables!$A$13:$A$16,0)) | K6: =INDEX(RateTables!$B$19:$C$28,MATCH(Policies!D6,RateTables!$A$19:$A$28,0),IF(Policies!C6="Frame",1,2)) | L6: =VLOOKUP(B6,AgeBands,2,TRUE) | M6: =VLOOKUP(C6,RoofBands,2,TRUE) | N6: =VLOOKUP(Policies!G6,AOIBands,2,TRUE) | O6: =VLOOKUP(Policies!H6,RateTables!$A$31:$B$35,2,TRUE) | P6: =VLOOKUP(MIN(Policies!L6,3),ClaimsTable,2,FALSE) | Q6: =ROUND(H6*I6*K6*L6*M6*N6*O6*P6,2) | R6: =IF(Policies!J6="Y",1,0) | S6: =IF(AND(Policies!L6=0,B6>=3),1,0) | T6: =IF(B6<=5,1,0) | U6: =IF(Policies!K6="Basic",1,0) | V6: =IF(Policies!K6="Fortified",1,0) | W6: =SUMPRODUCT(R6:V6,CreditPcts) | X6: =MIN(W6,CreditCap) | Y6: =ROUND(Q6*(1-X6),2) | Z6: =IF(Policies!I6="",0.02,Policies!I6) | AA6: =IFERROR(VLOOKUP(Z6,HurrDedTable,2,FALSE),1) | AB6: =IFERROR(INDEX(RateTables!$L$31:$L$33,MATCH(Policies!K6,RateTables!$K$31:$K$33,0)),1) | AC6: =ROUND(F6*D6*J6*AA6*AB6,2) | AD6: =MIN(AC6,Policies!G6*HurrCapPct) | AE6: =Y6+AD6 | AF6: =EDATE(Policies!M6,Policies!N6) | AG6: =ROUND(YEARFRAC(Policies!M6,AF6,3),4) | AH6: =ROUND(AE6*AG6,2) | AI6: =MAX(AH6,MinPremium) | AJ6: =ROUNDUP(AI6,0) | AK6: =VLOOKUP(Policies!N6,FeeTable,2,FALSE) | AL6: =ROUND(AJ6*AssessRate,2) | AM6: =ROUND((AJ6+AK6)*G6,2) | AN6: =AJ6+AK6+AL6+AM6 | AO6: =IF(OR(Policies!G6>1000000,C6>20,Policies!L6>=3),"REFER","OK") | AP6: =ROUND(AH6/D6,3) | AQ6: =Policies!B6&"-"&LEFT(Policies!C6,1)&TEXT(Policies!D6,"00")
A7: =Policies!A7 | B7: =IFERROR(DATEDIF(DATE(Policies!E7,1,1),Policies!M7,"y"),0) | C7: =Policies!F7*1 | D7: =Policies!G7/1000 | E7: =VLOOKUP(Policies!B7,BaseRates,2,FALSE) | F7: =VLOOKUP(Policies!B7,BaseRates,3,FALSE) | G7: =VLOOKUP(Policies!B7,BaseRates,4,FALSE) | H7: =ROUND(E7*D7,2) | I7: =INDEX(RateTables!$B$13:$B$16,MATCH(Policies!C7,RateTables!$A$13:$A$16,0)) | J7: =INDEX(RateTables!$C$13:$C$16,MATCH(Policies!C7,RateTables!$A$13:$A$16,0)) | K7: =INDEX(RateTables!$B$19:$C$28,MATCH(Policies!D7,RateTables!$A$19:$A$28,0),IF(Policies!C7="Frame",1,2)) | L7: =VLOOKUP(B7,AgeBands,2,TRUE) | M7: =VLOOKUP(C7,RoofBands,2,TRUE) | N7: =VLOOKUP(Policies!G7,AOIBands,2,TRUE) | O7: =VLOOKUP(Policies!H7,RateTables!$A$31:$B$35,2,TRUE) | P7: =VLOOKUP(MIN(Policies!L7,3),ClaimsTable,2,FALSE) | Q7: =ROUND(H7*I7*K7*L7*M7*N7*O7*P7,2) | R7: =IF(Policies!J7="Y",1,0) | S7: =IF(AND(Policies!L7=0,B7>=3),1,0) | T7: =IF(B7<=5,1,0) | U7: =IF(Policies!K7="Basic",1,0) | V7: =IF(Policies!K7="Fortified",1,0) | W7: =SUMPRODUCT(R7:V7,CreditPcts) | X7: =MIN(W7,CreditCap) | Y7: =ROUND(Q7*(1-X7),2) | Z7: =IF(Policies!I7="",0.02,Policies!I7) | AA7: =IFERROR(VLOOKUP(Z7,HurrDedTable,2,FALSE),1) | AB7: =IFERROR(INDEX(RateTables!$L$31:$L$33,MATCH(Policies!K7,RateTables!$K$31:$K$33,0)),1) | AC7: =ROUND(F7*D7*J7*AA7*AB7,2) | AD7: =MIN(AC7,Policies!G7*HurrCapPct) | AE7: =Y7+AD7 | AF7: =EDATE(Policies!M7,Policies!N7) | AG7: =ROUND(YEARFRAC(Policies!M7,AF7,3),4) | AH7: =ROUND(AE7*AG7,2) | AI7: =MAX(AH7,MinPremium) | AJ7: =ROUNDUP(AI7,0) | AK7: =VLOOKUP(Policies!N7,FeeTable,2,FALSE) | AL7: =ROUND(AJ7*AssessRate,2) | AM7: =ROUND((AJ7+AK7)*G7,2) | AN7: =AJ7+AK7+AL7+AM7 | AO7: =IF(OR(Policies!G7>1000000,C7>20,Policies!L7>=3),"REFER","OK") | AP7: =ROUND(AH7/D7,3) | AQ7: =Policies!B7&"-"&LEFT(Policies!C7,1)&TEXT(Policies!D7,"00")
A8: =Policies!A8 | B8: =IFERROR(DATEDIF(DATE(Policies!E8,1,1),Policies!M8,"y"),0) | C8: =Policies!F8*1 | D8: =Policies!G8/1000 | E8: =VLOOKUP(Policies!B8,BaseRates,2,FALSE) | F8: =VLOOKUP(Policies!B8,BaseRates,3,FALSE) | G8: =VLOOKUP(Policies!B8,BaseRates,4,FALSE) | H8: =ROUND(E8*D8,2) | I8: =INDEX(RateTables!$B$13:$B$16,MATCH(Policies!C8,RateTables!$A$13:$A$16,0)) | J8: =INDEX(RateTables!$C$13:$C$16,MATCH(Policies!C8,RateTables!$A$13:$A$16,0)) | K8: =INDEX(RateTables!$B$19:$C$28,MATCH(Policies!D8,RateTables!$A$19:$A$28,0),IF(Policies!C8="Frame",1,2)) | L8: =VLOOKUP(B8,AgeBands,2,TRUE) | M8: =VLOOKUP(C8,RoofBands,2,TRUE) | N8: =VLOOKUP(Policies!G8,AOIBands,2,TRUE) | O8: =VLOOKUP(Policies!H8,RateTables!$A$31:$B$35,2,TRUE) | P8: =VLOOKUP(MIN(Policies!L8,3),ClaimsTable,2,FALSE) | Q8: =ROUND(H8*I8*K8*L8*M8*N8*O8*P8,2) | R8: =IF(Policies!J8="Y",1,0) | S8: =IF(AND(Policies!L8=0,B8>=3),1,0) | T8: =IF(B8<=5,1,0) | U8: =IF(Policies!K8="Basic",1,0) | V8: =IF(Policies!K8="Fortified",1,0) | W8: =SUMPRODUCT(R8:V8,CreditPcts) | X8: =MIN(W8,CreditCap) | Y8: =ROUND(Q8*(1-X8),2) | Z8: =IF(Policies!I8="",0.02,Policies!I8) | AA8: =IFERROR(VLOOKUP(Z8,HurrDedTable,2,FALSE),1) | AB8: =IFERROR(INDEX(RateTables!$L$31:$L$33,MATCH(Policies!K8,RateTables!$K$31:$K$33,0)),1) | AC8: =ROUND(F8*D8*J8*AA8*AB8,2) | AD8: =MIN(AC8,Policies!G8*HurrCapPct) | AE8: =Y8+AD8 | AF8: =EDATE(Policies!M8,Policies!N8) | AG8: =ROUND(YEARFRAC(Policies!M8,AF8,3),4) | AH8: =ROUND(AE8*AG8,2) | AI8: =MAX(AH8,MinPremium) | AJ8: =ROUNDUP(AI8,0) | AK8: =VLOOKUP(Policies!N8,FeeTable,2,FALSE) | AL8: =ROUND(AJ8*AssessRate,2) | AM8: =ROUND((AJ8+AK8)*G8,2) | AN8: =AJ8+AK8+AL8+AM8 | AO8: =IF(OR(Policies!G8>1000000,C8>20,Policies!L8>=3),"REFER","OK") | AP8: =ROUND(AH8/D8,3) | AQ8: =Policies!B8&"-"&LEFT(Policies!C8,1)&TEXT(Policies!D8,"00")
A9: =Policies!A9 | B9: =IFERROR(DATEDIF(DATE(Policies!E9,1,1),Policies!M9,"y"),0) | C9: =Policies!F9*1 | D9: =Policies!G9/1000 | E9: =VLOOKUP(Policies!B9,BaseRates,2,FALSE) | F9: =VLOOKUP(Policies!B9,BaseRates,3,FALSE) | G9: =VLOOKUP(Policies!B9,BaseRates,4,FALSE) | H9: =ROUND(E9*D9,2) | I9: =INDEX(RateTables!$B$13:$B$16,MATCH(Policies!C9,RateTables!$A$13:$A$16,0)) | J9: =INDEX(RateTables!$C$13:$C$16,MATCH(Policies!C9,RateTables!$A$13:$A$16,0)) | K9: =INDEX(RateTables!$B$19:$C$28,MATCH(Policies!D9,RateTables!$A$19:$A$28,0),IF(Policies!C9="Frame",1,2)) | L9: =VLOOKUP(B9,AgeBands,2,TRUE) | M9: =VLOOKUP(C9,RoofBands,2,TRUE) | N9: =VLOOKUP(Policies!G9,AOIBands,2,TRUE) | O9: =VLOOKUP(Policies!H9,RateTables!$A$31:$B$35,2,TRUE) | P9: =VLOOKUP(MIN(Policies!L9,3),ClaimsTable,2,FALSE) | Q9: =ROUND(H9*I9*K9*L9*M9*N9*O9*P9,2) | R9: =IF(Policies!J9="Y",1,0) | S9: =IF(AND(Policies!L9=0,B9>=3),1,0) | T9: =IF(B9<=5,1,0) | U9: =IF(Policies!K9="Basic",1,0) | V9: =IF(Policies!K9="Fortified",1,0) | W9: =SUMPRODUCT(R9:V9,CreditPcts) | X9: =MIN(W9,CreditCap) | Y9: =ROUND(Q9*(1-X9),2) | Z9: =IF(Policies!I9="",0.02,Policies!I9) | AA9: =IFERROR(VLOOKUP(Z9,HurrDedTable,2,FALSE),1) | AB9: =IFERROR(INDEX(RateTables!$L$31:$L$33,MATCH(Policies!K9,RateTables!$K$31:$K$33,0)),1) | AC9: =ROUND(F9*D9*J9*AA9*AB9,2) | AD9: =MIN(AC9,Policies!G9*HurrCapPct) | AE9: =Y9+AD9 | AF9: =EDATE(Policies!M9,Policies!N9) | AG9: =ROUND(YEARFRAC(Policies!M9,AF9,3),4) | AH9: =ROUND(AE9*AG9,2) | AI9: =MAX(AH9,MinPremium) | AJ9: =ROUNDUP(AI9,0) | AK9: =VLOOKUP(Policies!N9,FeeTable,2,FALSE) | AL9: =ROUND(AJ9*AssessRate,2) | AM9: =ROUND((AJ9+AK9)*G9,2) | AN9: =AJ9+AK9+AL9+AM9 | AO9: =IF(OR(Policies!G9>1000000,C9>20,Policies!L9>=3),"REFER","OK") | AP9: =ROUND(AH9/D9,3) | AQ9: =Policies!B9&"-"&LEFT(Policies!C9,1)&TEXT(Policies!D9,"00")
A10: =Policies!A10 | B10: =IFERROR(DATEDIF(DATE(Policies!E10,1,1),Policies!M10,"y"),0) | C10: =Policies!F10*1 | D10: =Policies!G10/1000 | E10: =VLOOKUP(Policies!B10,BaseRates,2,FALSE) | F10: =VLOOKUP(Policies!B10,BaseRates,3,FALSE) | G10: =VLOOKUP(Policies!B10,BaseRates,4,FALSE) | H10: =ROUND(E10*D10,2) | I10: =INDEX(RateTables!$B$13:$B$16,MATCH(Policies!C10,RateTables!$A$13:$A$16,0)) | J10: =INDEX(RateTables!$C$13:$C$16,MATCH(Policies!C10,RateTables!$A$13:$A$16,0)) | K10: =INDEX(RateTables!$B$19:$C$28,MATCH(Policies!D10,RateTables!$A$19:$A$28,0),IF(Policies!C10="Frame",1,2)) | L10: =VLOOKUP(B10,AgeBands,2,TRUE) | M10: =VLOOKUP(C10,RoofBands,2,TRUE) | N10: =VLOOKUP(Policies!G10,AOIBands,2,TRUE) | O10: =VLOOKUP(Policies!H10,RateTables!$A$31:$B$35,2,TRUE) | P10: =VLOOKUP(MIN(Policies!L10,3),ClaimsTable,2,FALSE) | Q10: =ROUND(H10*I10*K10*L10*M10*N10*O10*P10,2) | R10: =IF(Policies!J10="Y",1,0) | S10: =IF(AND(Policies!L10=0,B10>=3),1,0) | T10: =IF(B10<=5,1,0) | U10: =IF(Policies!K10="Basic",1,0) | V10: =IF(Policies!K10="Fortified",1,0) | W10: =SUMPRODUCT(R10:V10,CreditPcts) | X10: =MIN(W10,CreditCap) | Y10: =ROUND(Q10*(1-X10),2) | Z10: =IF(Policies!I10="",0.02,Policies!I10) | AA10: =IFERROR(VLOOKUP(Z10,HurrDedTable,2,FALSE),1) | AB10: =IFERROR(INDEX(RateTables!$L$31:$L$33,MATCH(Policies!K10,RateTables!$K$31:$K$33,0)),1) | AC10: =ROUND(F10*D10*J10*AA10*AB10,2) | AD10: =MIN(AC10,Policies!G10*HurrCapPct) | AE10: =Y10+AD10 | AF10: =EDATE(Policies!M10,Policies!N10) | AG10: =ROUND(YEARFRAC(Policies!M10,AF10,3),4) | AH10: =ROUND(AE10*AG10,2) | AI10: =MAX(AH10,MinPremium) | AJ10: =ROUNDUP(AI10,0) | AK10: =VLOOKUP(Policies!N10,FeeTable,2,FALSE) | AL10: =ROUND(AJ10*AssessRate,2) | AM10: =ROUND((AJ10+AK10)*G10,2) | AN10: =AJ10+AK10+AL10+AM10 | AO10: =IF(OR(Policies!G10>1000000,C10>20,Policies!L10>=3),"REFER","OK") | AP10: =ROUND(AH10/D10,3) | AQ10: =Policies!B10&"-"&LEFT(Policies!C10,1)&TEXT(Policies!D10,"00")
A11: =Policies!A11 | B11: =IFERROR(DATEDIF(DATE(Policies!E11,1,1),Policies!M11,"y"),0) | C11: =Policies!F11*1 | D11: =Policies!G11/1000 | E11: =VLOOKUP(Policies!B11,BaseRates,2,FALSE) | F11: =VLOOKUP(Policies!B11,BaseRates,3,FALSE) | G11: =VLOOKUP(Policies!B11,BaseRates,4,FALSE) | H11: =ROUND(E11*D11,2) | I11: =INDEX(RateTables!$B$13:$B$16,MATCH(Policies!C11,RateTables!$A$13:$A$16,0)) | J11: =INDEX(RateTables!$C$13:$C$16,MATCH(Policies!C11,RateTables!$A$13:$A$16,0)) | K11: =INDEX(RateTables!$B$19:$C$28,MATCH(Policies!D11,RateTables!$A$19:$A$28,0),IF(Policies!C11="Frame",1,2)) | L11: =VLOOKUP(B11,AgeBands,2,TRUE) | M11: =VLOOKUP(C11,RoofBands,2,TRUE) | N11: =VLOOKUP(Policies!G11,AOIBands,2,TRUE) | O11: =VLOOKUP(Policies!H11,RateTables!$A$31:$B$35,2,TRUE) | P11: =VLOOKUP(MIN(Policies!L11,3),ClaimsTable,2,FALSE) | Q11: =ROUND(H11*I11*K11*L11*M11*N11*O11*P11,2) | R11: =IF(Policies!J11="Y",1,0) | S11: =IF(AND(Policies!L11=0,B11>=3),1,0) | T11: =IF(B11<=5,1,0) | U11: =IF(Policies!K11="Basic",1,0) | V11: =IF(Policies!K11="Fortified",1,0) | W11: =SUMPRODUCT(R11:V11,CreditPcts) | X11: =MIN(W11,CreditCap) | Y11: =ROUND(Q11*(1-X11),2) | Z11: =IF(Policies!I11="",0.02,Policies!I11) | AA11: =IFERROR(VLOOKUP(Z11,HurrDedTable,2,FALSE),1) | AB11: =IFERROR(INDEX(RateTables!$L$31:$L$33,MATCH(Policies!K11,RateTables!$K$31:$K$33,0)),1) | AC11: =ROUND(F11*D11*J11*AA11*AB11,2) | AD11: =MIN(AC11,Policies!G11*HurrCapPct) | AE11: =Y11+AD11 | AF11: =EDATE(Policies!M11,Policies!N11) | AG11: =ROUND(YEARFRAC(Policies!M11,AF11,3),4) | AH11: =ROUND(AE11*AG11,2) | AI11: =MAX(AH11,MinPremium) | AJ11: =ROUNDUP(AI11,0) | AK11: =VLOOKUP(Policies!N11,FeeTable,2,FALSE) | AL11: =ROUND(AJ11*AssessRate,2) | AM11: =ROUND((AJ11+AK11)*G11,2) | AN11: =AJ11+AK11+AL11+AM11 | AO11: =IF(OR(Policies!G11>1000000,C11>20,Policies!L11>=3),"REFER","OK") | AP11: =ROUND(AH11/D11,3) | AQ11: =Policies!B11&"-"&LEFT(Policies!C11,1)&TEXT(Policies!D11,"00")
A12: =Policies!A12 | B12: =IFERROR(DATEDIF(DATE(Policies!E12,1,1),Policies!M12,"y"),0) | C12: =Policies!F12*1 | D12: =Policies!G12/1000 | E12: =VLOOKUP(Policies!B12,BaseRates,2,FALSE) | F12: =VLOOKUP(Policies!B12,BaseRates,3,FALSE) | G12: =VLOOKUP(Policies!B12,BaseRates,4,FALSE) | H12: =ROUND(E12*D12,2) | I12: =INDEX(RateTables!$B$13:$B$16,MATCH(Policies!C12,RateTables!$A$13:$A$16,0)) | J12: =INDEX(RateTables!$C$13:$C$16,MATCH(Policies!C12,RateTables!$A$13:$A$16,0)) | K12: =INDEX(RateTables!$B$19:$C$28,MATCH(Policies!D12,RateTables!$A$19:$A$28,0),IF(Policies!C12="Frame",1,2)) | L12: =VLOOKUP(B12,AgeBands,2,TRUE) | M12: =VLOOKUP(C12,RoofBands,2,TRUE) | N12: =VLOOKUP(Policies!G12,AOIBands,2,TRUE) | O12: =VLOOKUP(Policies!H12,RateTables!$A$31:$B$35,2,TRUE) | P12: =VLOOKUP(MIN(Policies!L12,3),ClaimsTable,2,FALSE) | Q12: =ROUND(H12*I12*K12*L12*M12*N12*O12*P12,2) | R12: =IF(Policies!J12="Y",1,0) | S12: =IF(AND(Policies!L12=0,B12>=3),1,0) | T12: =IF(B12<=5,1,0) | U12: =IF(Policies!K12="Basic",1,0) | V12: =IF(Policies!K12="Fortified",1,0) | W12: =SUMPRODUCT(R12:V12,CreditPcts) | X12: =MIN(W12,CreditCap) | Y12: =ROUND(Q12*(1-X12),2) | Z12: =IF(Policies!I12="",0.02,Policies!I12) | AA12: =IFERROR(VLOOKUP(Z12,HurrDedTable,2,FALSE),1) | AB12: =IFERROR(INDEX(RateTables!$L$31:$L$33,MATCH(Policies!K12,RateTables!$K$31:$K$33,0)),1) | AC12: =ROUND(F12*D12*J12*AA12*AB12,2) | AD12: =MIN(AC12,Policies!G12*HurrCapPct) | AE12: =Y12+AD12 | AF12: =EDATE(Policies!M12,Policies!N12) | AG12: =ROUND(YEARFRAC(Policies!M12,AF12,3),4) | AH12: =ROUND(AE12*AG12,2) | AI12: =MAX(AH12,MinPremium) | AJ12: =ROUNDUP(AI12,0) | AK12: =VLOOKUP(Policies!N12,FeeTable,2,FALSE) | AL12: =ROUND(AJ12*AssessRate,2) | AM12: =ROUND((AJ12+AK12)*G12,2) | AN12: =AJ12+AK12+AL12+AM12 | AO12: =IF(OR(Policies!G12>1000000,C12>20,Policies!L12>=3),"REFER","OK") | AP12: =ROUND(AH12/D12,3) | AQ12: =Policies!B12&"-"&LEFT(Policies!C12,1)&TEXT(Policies!D12,"00")
A13: =Policies!A13 | B13: =IFERROR(DATEDIF(DATE(Policies!E13,1,1),Policies!M13,"y"),0) | C13: =Policies!F13*1 | D13: =Policies!G13/1000 | E13: =VLOOKUP(Policies!B13,BaseRates,2,FALSE) | F13: =VLOOKUP(Policies!B13,BaseRates,3,FALSE) | G13: =VLOOKUP(Policies!B13,BaseRates,4,FALSE) | H13: =ROUND(E13*D13,2) | I13: =INDEX(RateTables!$B$13:$B$16,MATCH(Policies!C13,RateTables!$A$13:$A$16,0)) | J13: =INDEX(RateTables!$C$13:$C$16,MATCH(Policies!C13,RateTables!$A$13:$A$16,0)) | K13: =INDEX(RateTables!$B$19:$C$28,MATCH(Policies!D13,RateTables!$A$19:$A$28,0),IF(Policies!C13="Frame",1,2)) | L13: =VLOOKUP(B13,AgeBands,2,TRUE) | M13: =VLOOKUP(C13,RoofBands,2,TRUE) | N13: =VLOOKUP(Policies!G13,AOIBands,2,TRUE) | O13: =VLOOKUP(Policies!H13,RateTables!$A$31:$B$35,2,TRUE) | P13: =VLOOKUP(MIN(Policies!L13,3),ClaimsTable,2,FALSE) | Q13: =ROUND(H13*I13*K13*L13*M13*N13*O13*P13,2) | R13: =IF(Policies!J13="Y",1,0) | S13: =IF(AND(Policies!L13=0,B13>=3),1,0) | T13: =IF(B13<=5,1,0) | U13: =IF(Policies!K13="Basic",1,0) | V13: =IF(Policies!K13="Fortified",1,0) | W13: =SUMPRODUCT(R13:V13,CreditPcts) | X13: =MIN(W13,CreditCap) | Y13: =ROUND(Q13*(1-X13),2) | Z13: =IF(Policies!I13="",0.02,Policies!I13) | AA13: =IFERROR(VLOOKUP(Z13,HurrDedTable,2,FALSE),1) | AB13: =IFERROR(INDEX(RateTables!$L$31:$L$33,MATCH(Policies!K13,RateTables!$K$31:$K$33,0)),1) | AC13: =ROUND(F13*D13*J13*AA13*AB13,2) | AD13: =MIN(AC13,Policies!G13*HurrCapPct) | AE13: =Y13+AD13 | AF13: =EDATE(Policies!M13,Policies!N13) | AG13: =ROUND(YEARFRAC(Policies!M13,AF13,3),4) | AH13: =ROUND(AE13*AG13,2) | AI13: =MAX(AH13,MinPremium) | AJ13: =ROUNDUP(AI13,0) | AK13: =VLOOKUP(Policies!N13,FeeTable,2,FALSE) | AL13: =ROUND(AJ13*AssessRate,2) | AM13: =ROUND((AJ13+AK13)*G13,2) | AN13: =AJ13+AK13+AL13+AM13 | AO13: =IF(OR(Policies!G13>1000000,C13>20,Policies!L13>=3),"REFER","OK") | AP13: =ROUND(AH13/D13,3) | AQ13: =Policies!B13&"-"&LEFT(Policies!C13,1)&TEXT(Policies!D13,"00")
... A16: =Policies!A16 | B16: =IFERROR(DATEDIF(DATE(Policies!E16,1,1),Policies!M16,"y"),0) | C16: =Policies!F16*1 | D16: =Policies!G16/1000 | E16: =VLOOKUP(Policies!B16,BaseRates,2,FALSE) | F16: =VLOOKUP(Policies!B16,BaseRates,3,FALSE) | G16: =VLOOKUP(Policies!B16,BaseRates,4,FALSE) | H16: =ROUND(E16*D16,2) | I16: =INDEX(RateTables!$B$13:$B$16,MATCH(Policies!C16,RateTables!$A$13:$A$16,0)) | J16: =INDEX(RateTables!$C$13:$C$16,MATCH(Policies!C16,RateTables!$A$13:$A$16,0)) | K16: =INDEX(RateTables!$B$19:$C$28,MATCH(Policies!D16,RateTables!$A$19:$A$28,0),IF(Policies!C16="Frame",1,2)) | L16: =VLOOKUP(B16,AgeBands,2,TRUE) | M16: =VLOOKUP(C16,RoofBands,2,TRUE) | N16: =VLOOKUP(Policies!G16,AOIBands,2,TRUE) | O16: =VLOOKUP(Policies!H16,RateTables!$A$31:$B$35,2,TRUE) | P16: =VLOOKUP(MIN(Policies!L16,3),ClaimsTable,2,FALSE) | Q16: =ROUND(H16*I16*K16*L16*M16*N16*O16*P16,2) | R16: =IF(Policies!J16="Y",1,0) | S16: =IF(AND(Policies!L16=0,B16>=3),1,0) | T16: =IF(B16<=5,1,0) | U16: =IF(Policies!K16="Basic",1,0) | V16: =IF(Policies!K16="Fortified",1,0) | W16: =SUMPRODUCT(R16:V16,CreditPcts) | X16: =MIN(W16,CreditCap) | Y16: =ROUND(Q16*(1-X16),2) | Z16: =IF(Policies!I16="",0.02,Policies!I16) | AA16: =IFERROR(VLOOKUP(Z16,HurrDedTable,2,FALSE),1) | AB16: =IFERROR(INDEX(RateTables!$L$31:$L$33,MATCH(Policies!K16,RateTables!$K$31:$K$33,0)),1) | AC16: =ROUND(F16*D16*J16*AA16*AB16,2) | AD16: =MIN(AC16,Policies!G16*HurrCapPct) | AE16: =Y16+AD16 | AF16: =EDATE(Policies!M16,Policies!N16) | AG16: =ROUND(YEARFRAC(Policies!M16,AF16,3),4) | AH16: =ROUND(AE16*AG16,2) | AI16: =MAX(AH16,MinPremium) | AJ16: =ROUNDUP(AI16,0) | AK16: =VLOOKUP(Policies!N16,FeeTable,2,FALSE) | AL16: =ROUND(AJ16*AssessRate,2) | AM16: =ROUND((AJ16+AK16)*G16,2) | AN16: =AJ16+AK16+AL16+AM16 | AO16: =IF(OR(Policies!G16>1000000,C16>20,Policies!L16>=3),"REFER","OK") | AP16: =ROUND(AH16/D16,3) | AQ16: =Policies!B16&"-"&LEFT(Policies!C16,1)&TEXT(Policies!D16,"00")
A17: =Policies!A17 | B17: =IFERROR(DATEDIF(DATE(Policies!E17,1,1),Policies!M17,"y"),0) | C17: =Policies!F17*1 | D17: =Policies!G17/1000 | E17: =VLOOKUP(Policies!B17,BaseRates,2,FALSE) | F17: =VLOOKUP(Policies!B17,BaseRates,3,FALSE) | G17: =VLOOKUP(Policies!B17,BaseRates,4,FALSE) | H17: =ROUND(E17*D17,2) | I17: =INDEX(RateTables!$B$13:$B$16,MATCH(Policies!C17,RateTables!$A$13:$A$16,0)) | J17: =INDEX(RateTables!$C$13:$C$16,MATCH(Policies!C17,RateTables!$A$13:$A$16,0)) | K17: =INDEX(RateTables!$B$19:$C$28,MATCH(Policies!D17,RateTables!$A$19:$A$28,0),IF(Policies!C17="Frame",1,2)) | L17: =VLOOKUP(B17,AgeBands,2,TRUE) | M17: =VLOOKUP(C17,RoofBands,2,TRUE) | N17: =VLOOKUP(Policies!G17,AOIBands,2,TRUE) | O17: =VLOOKUP(Policies!H17,RateTables!$A$31:$B$35,2,TRUE) | P17: =VLOOKUP(MIN(Policies!L17,3),ClaimsTable,2,FALSE) | Q17: =ROUND(H17*I17*K17*L17*M17*N17*O17*P17,2) | R17: =IF(Policies!J17="Y",1,0) | S17: =IF(AND(Policies!L17=0,B17>=3),1,0) | T17: =IF(B17<=5,1,0) | U17: =IF(Policies!K17="Basic",1,0) | V17: =IF(Policies!K17="Fortified",1,0) | W17: =SUMPRODUCT(R17:V17,CreditPcts) | X17: =MIN(W17,CreditCap) | Y17: =ROUND(Q17*(1-X17),2) | Z17: =IF(Policies!I17="",0.02,Policies!I17) | AA17: =IFERROR(VLOOKUP(Z17,HurrDedTable,2,FALSE),1) | AB17: =IFERROR(INDEX(RateTables!$L$31:$L$33,MATCH(Policies!K17,RateTables!$K$31:$K$33,0)),1) | AC17: =ROUND(F17*D17*J17*AA17*AB17,2) | AD17: =MIN(AC17,Policies!G17*HurrCapPct) | AE17: =Y17+AD17 | AF17: =EDATE(Policies!M17,Policies!N17) | AG17: =ROUND(YEARFRAC(Policies!M17,AF17,3),4) | AH17: =ROUND(AE17*AG17,2) | AI17: =MAX(AH17,MinPremium) | AJ17: =ROUNDUP(AI17,0) | AK17: =VLOOKUP(Policies!N17,FeeTable,2,FALSE) | AL17: =ROUND(AJ17*AssessRate,2) | AM17: 48.17 | AN17: =AJ17+AK17+AL17+AM17 | AO17: =IF(OR(Policies!G17>1000000,C17>20,Policies!L17>=3),"REFER","OK") | AP17: =ROUND(AH17/D17,3) | AQ17: =Policies!B17&"-"&LEFT(Policies!C17,1)&TEXT(Policies!D17,"00")
A18: =Policies!A18 | B18: =IFERROR(DATEDIF(DATE(Policies!E18,1,1),Policies!M18,"y"),0) | C18: =Policies!F18*1 | D18: =Policies!G18/1000 | E18: =VLOOKUP(Policies!B18,BaseRates,2,FALSE) | F18: =VLOOKUP(Policies!B18,BaseRates,3,FALSE) | G18: =VLOOKUP(Policies!B18,BaseRates,4,FALSE) | H18: =ROUND(E18*D18,2) | I18: =INDEX(RateTables!$B$13:$B$16,MATCH(Policies!C18,RateTables!$A$13:$A$16,0)) | J18: =INDEX(RateTables!$C$13:$C$16,MATCH(Policies!C18,RateTables!$A$13:$A$16,0)) | K18: =INDEX(RateTables!$B$19:$C$28,MATCH(Policies!D18,RateTables!$A$19:$A$28,0),IF(Policies!C18="Frame",1,2)) | L18: =VLOOKUP(B18,AgeBands,2,TRUE) | M18: =VLOOKUP(C18,RoofBands,2,TRUE) | N18: =VLOOKUP(Policies!G18,AOIBands,2,TRUE) | O18: =VLOOKUP(Policies!H18,RateTables!$A$31:$B$35,2,TRUE) | P18: =VLOOKUP(MIN(Policies!L18,3),ClaimsTable,2,FALSE) | Q18: =ROUND(H18*I18*K18*L18*M18*N18*O18*P18,2) | R18: =IF(Policies!J18="Y",1,0) | S18: =IF(AND(Policies!L18=0,B18>=3),1,0) | T18: =IF(B18<=5,1,0) | U18: =IF(Policies!K18="Basic",1,0) | V18: =IF(Policies!K18="Fortified",1,0) | W18: =SUMPRODUCT(R18:V18,CreditPcts) | X18: =MIN(W18,CreditCap) | Y18: =ROUND(Q18*(1-X18),2) | Z18: =IF(Policies!I18="",0.02,Policies!I18) | AA18: =IFERROR(VLOOKUP(Z18,HurrDedTable,2,FALSE),1) | AB18: =IFERROR(INDEX(RateTables!$L$31:$L$33,MATCH(Policies!K18,RateTables!$K$31:$K$33,0)),1) | AC18: =ROUND(F18*D18*J18*AA18*AB18,2) | AD18: =MIN(AC18,Policies!G18*HurrCapPct) | AE18: =Y18+AD18 | AF18: =EDATE(Policies!M18,Policies!N18) | AG18: =ROUND(YEARFRAC(Policies!M18,AF18,3),4) | AH18: =ROUND(AE18*AG18,2) | AI18: =MAX(AH18,MinPremium) | AJ18: =ROUNDUP(AI18,0) | AK18: =VLOOKUP(Policies!N18,FeeTable,2,FALSE) | AL18: =ROUND(AJ18*AssessRate,2) | AM18: =ROUND((AJ18+AK18)*G18,2) | AN18: =AJ18+AK18+AL18+AM18 | AO18: =IF(OR(Policies!G18>1000000,C18>20,Policies!L18>=3),"REFER","OK") | AP18: =ROUND(AH18/D18,3) | AQ18: =Policies!B18&"-"&LEFT(Policies!C18,1)&TEXT(Policies!D18,"00")
A19: =Policies!A19 | B19: =IFERROR(DATEDIF(DATE(Policies!E19,1,1),Policies!M19,"y"),0) | C19: =Policies!F19*1 | D19: =Policies!G19/1000 | E19: =VLOOKUP(Policies!B19,BaseRates,2,FALSE) | F19: =VLOOKUP(Policies!B19,BaseRates,3,FALSE) | G19: =VLOOKUP(Policies!B19,BaseRates,4,FALSE) | H19: =ROUND(E19*D19,2) | I19: =INDEX(RateTables!$B$13:$B$16,MATCH(Policies!C19,RateTables!$A$13:$A$16,0)) | J19: =INDEX(RateTables!$C$13:$C$16,MATCH(Policies!C19,RateTables!$A$13:$A$16,0)) | K19: =INDEX(RateTables!$B$19:$C$28,MATCH(Policies!D19,RateTables!$A$19:$A$28,0),IF(Policies!C19="Frame",1,2)) | L19: =VLOOKUP(B19,AgeBands,2,TRUE) | M19: =VLOOKUP(C19,RoofBands,2,TRUE) | N19: =VLOOKUP(Policies!G19,AOIBands,2,TRUE) | O19: =VLOOKUP(Policies!H19,RateTables!$A$31:$B$35,2,TRUE) | P19: =VLOOKUP(MIN(Policies!L19,3),ClaimsTable,2,FALSE) | Q19: =ROUND(H19*I19*K19*L19*M19*N19*O19*P19,2) | R19: =IF(Policies!J19="Y",1,0) | S19: =IF(AND(Policies!L19=0,B19>=3),1,0) | T19: =IF(B19<=5,1,0) | U19: =IF(Policies!K19="Basic",1,0) | V19: =IF(Policies!K19="Fortified",1,0) | W19: =SUMPRODUCT(R19:V19,CreditPcts) | X19: =MIN(W19,CreditCap) | Y19: =ROUND(Q19*(1-X19),2) | Z19: =IF(Policies!I19="",0.02,Policies!I19) | AA19: =IFERROR(VLOOKUP(Z19,HurrDedTable,2,FALSE),1) | AB19: =IFERROR(INDEX(RateTables!$L$31:$L$33,MATCH(Policies!K19,RateTables!$K$31:$K$33,0)),1) | AC19: =ROUND(F19*D19*J19*AA19*AB19,2) | AD19: =MIN(AC19,Policies!G19*HurrCapPct) | AE19: =Y19+AD19 | AF19: =EDATE(Policies!M19,Policies!N19) | AG19: =ROUND(YEARFRAC(Policies!M19,AF19,3),4) | AH19: =ROUND(AE19*AG19,2) | AI19: =MAX(AH19,MinPremium) | AJ19: =ROUNDUP(AI19,0) | AK19: =VLOOKUP(Policies!N19,FeeTable,2,FALSE) | AL19: =ROUND(AJ19*AssessRate,2) | AM19: =ROUND((AJ19+AK19)*G19,2) | AN19: =AJ19+AK19+AL19+AM19 | AO19: =IF(OR(Policies!G19>1000000,C19>20,Policies!L19>=3),"REFER","OK") | AP19: =ROUND(AH19/D19,3) | AQ19: =Policies!B19&"-"&LEFT(Policies!C19,1)&TEXT(Policies!D19,"00")
A20: =Policies!A20 | B20: =IFERROR(DATEDIF(DATE(Policies!E20,1,1),Policies!M20,"y"),0) | C20: =Policies!F20*1 | D20: =Policies!G20/1000 | E20: =VLOOKUP(Policies!B20,BaseRates,2,FALSE) | F20: =VLOOKUP(Policies!B20,BaseRates,3,FALSE) | G20: =VLOOKUP(Policies!B20,BaseRates,4,FALSE) | H20: =ROUND(E20*D20,2) | I20: =INDEX(RateTables!$B$13:$B$16,MATCH(Policies!C20,RateTables!$A$13:$A$16,0)) | J20: =INDEX(RateTables!$C$13:$C$16,MATCH(Policies!C20,RateTables!$A$13:$A$16,0)) | K20: =INDEX(RateTables!$B$19:$C$28,MATCH(Policies!D20,RateTables!$A$19:$A$28,0),IF(Policies!C20="Frame",1,2)) | L20: =VLOOKUP(B20,AgeBands,2,TRUE) | M20: =VLOOKUP(C20,RoofBands,2,TRUE) | N20: =VLOOKUP(Policies!G20,AOIBands,2,TRUE) | O20: =VLOOKUP(Policies!H20,RateTables!$A$31:$B$35,2,TRUE) | P20: =VLOOKUP(MIN(Policies!L20,3),ClaimsTable,2,FALSE) | Q20: =ROUND(H20*I20*K20*L20*M20*N20*O20*P20,2) | R20: =IF(Policies!J20="Y",1,0) | S20: =IF(AND(Policies!L20=0,B20>=3),1,0) | T20: =IF(B20<=5,1,0) | U20: =IF(Policies!K20="Basic",1,0) | V20: =IF(Policies!K20="Fortified",1,0) | W20: =SUMPRODUCT(R20:V20,CreditPcts) | X20: =MIN(W20,CreditCap) | Y20: =ROUND(Q20*(1-X20),2) | Z20: =IF(Policies!I20="",0.02,Policies!I20) | AA20: =IFERROR(VLOOKUP(Z20,HurrDedTable,2,FALSE),1) | AB20: =IFERROR(INDEX(RateTables!$L$31:$L$33,MATCH(Policies!K20,RateTables!$K$31:$K$33,0)),1) | AC20: =ROUND(F20*D20*J20*AA20*AB20,2) | AD20: =MIN(AC20,Policies!G20*HurrCapPct) | AE20: =Y20+AD20 | AF20: =EDATE(Policies!M20,Policies!N20) | AG20: =ROUND(YEARFRAC(Policies!M20,AF20,3),4) | AH20: =ROUND(AE20*AG20,2) | AI20: =MAX(AH20,MinPremium) | AJ20: =ROUNDUP(AI20,0) | AK20: =VLOOKUP(Policies!N20,FeeTable,2,FALSE) | AL20: =ROUND(AJ20*AssessRate,2) | AM20: =ROUND((AJ20+AK20)*G20,2) | AN20: =AJ20+AK20+AL20+AM20 | AO20: =IF(OR(Policies!G20>1000000,C20>20,Policies!L20>=3),"REFER","OK") | AP20: =ROUND(AH20/D20,3) | AQ20: =Policies!B20&"-"&LEFT(Policies!C20,1)&TEXT(Policies!D20,"00")
A21: =Policies!A21 | B21: =IFERROR(DATEDIF(DATE(Policies!E21,1,1),Policies!M21,"y"),0) | C21: =Policies!F21*1 | D21: =Policies!G21/1000 | E21: =VLOOKUP(Policies!B21,BaseRates,2,FALSE) | F21: =VLOOKUP(Policies!B21,BaseRates,3,FALSE) | G21: =VLOOKUP(Policies!B21,BaseRates,4,FALSE) | H21: =ROUND(E21*D21,2) | I21: =INDEX(RateTables!$B$13:$B$16,MATCH(Policies!C21,RateTables!$A$13:$A$16,0)) | J21: =INDEX(RateTables!$C$13:$C$16,MATCH(Policies!C21,RateTables!$A$13:$A$16,0)) | K21: =INDEX(RateTables!$B$19:$C$28,MATCH(Policies!D21,RateTables!$A$19:$A$28,0),IF(Policies!C21="Frame",1,2)) | L21: =VLOOKUP(B21,AgeBands,2,TRUE) | M21: =VLOOKUP(C21,RoofBands,2,TRUE) | N21: =VLOOKUP(Policies!G21,AOIBands,2,TRUE) | O21: =VLOOKUP(Policies!H21,RateTables!$A$31:$B$35,2,TRUE) | P21: =VLOOKUP(MIN(Policies!L21,3),ClaimsTable,2,FALSE) | Q21: =ROUND(H21*I21*K21*L21*M21*N21*O21*P21,2) | R21: =IF(Policies!J21="Y",1,0) | S21: =IF(AND(Policies!L21=0,B21>=3),1,0) | T21: =IF(B21<=5,1,0) | U21: =IF(Policies!K21="Basic",1,0) | V21: =IF(Policies!K21="Fortified",1,0) | W21: =SUMPRODUCT(R21:V21,CreditPcts) | X21: =MIN(W21,CreditCap) | Y21: =ROUND(Q21*(1-X21),2) | Z21: =IF(Policies!I21="",0.02,Policies!I21) | AA21: =IFERROR(VLOOKUP(Z21,HurrDedTable,2,FALSE),1) | AB21: =IFERROR(INDEX(RateTables!$L$31:$L$33,MATCH(Policies!K21,RateTables!$K$31:$K$33,0)),1) | AC21: =ROUND(F21*D21*J21*AA21*AB21,2) | AD21: =MIN(AC21,Policies!G21*HurrCapPct) | AE21: =Y21+AD21 | AF21: =EDATE(Policies!M21,Policies!N21) | AG21: =ROUND(YEARFRAC(Policies!M21,AF21,3),4) | AH21: =ROUND(AE21*AG21,2) | AI21: =MAX(AH21,MinPremium) | AJ21: =ROUNDUP(AI21,0) | AK21: =VLOOKUP(Policies!N21,FeeTable,2,FALSE) | AL21: =ROUND(AJ21*AssessRate,2) | AM21: =ROUND((AJ21+AK21)*G21,2) | AN21: =AJ21+AK21+AL21+AM21 | AO21: =IF(OR(Policies!G21>1000000,C21>20,Policies!L21>=3),"REFER","OK") | AP21: =ROUND(AH21/D21,3) | AQ21: =Policies!B21&"-"&LEFT(Policies!C21,1)&TEXT(Policies!D21,"00")
A22: =Policies!A22 | B22: =IFERROR(DATEDIF(DATE(Policies!E22,1,1),Policies!M22,"y"),0) | C22: =Policies!F22*1 | D22: =Policies!G22/1000 | E22: =VLOOKUP(Policies!B22,BaseRates,2,FALSE) | F22: =VLOOKUP(Policies!B22,BaseRates,3,FALSE) | G22: =VLOOKUP(Policies!B22,BaseRates,4,FALSE) | H22: =ROUND(E22*D22,2) | I22: =INDEX(RateTables!$B$13:$B$16,MATCH(Policies!C22,RateTables!$A$13:$A$16,0)) | J22: =INDEX(RateTables!$C$13:$C$16,MATCH(Policies!C22,RateTables!$A$13:$A$16,0)) | K22: =INDEX(RateTables!$B$19:$C$28,MATCH(Policies!D22,RateTables!$A$19:$A$28,0),IF(Policies!C22="Frame",1,2)) | L22: =VLOOKUP(B22,AgeBands,2,TRUE) | M22: =VLOOKUP(C22,RoofBands,2,TRUE) | N22: =VLOOKUP(Policies!G22,AOIBands,2,TRUE) | O22: =VLOOKUP(Policies!H22,RateTables!$A$31:$B$35,2,TRUE) | P22: =VLOOKUP(MIN(Policies!L22,3),ClaimsTable,2,FALSE) | Q22: =ROUND(H22*I22*K22*L22*M22*N22*O22*P22,2) | R22: =IF(Policies!J22="Y",1,0) | S22: =IF(AND(Policies!L22=0,B22>=3),1,0) | T22: =IF(B22<=5,1,0) | U22: =IF(Policies!K22="Basic",1,0) | V22: =IF(Policies!K22="Fortified",1,0) | W22: =SUMPRODUCT(R22:V22,CreditPcts) | X22: =MIN(W22,CreditCap) | Y22: =ROUND(Q22*(1-X22),2) | Z22: =IF(Policies!I22="",0.02,Policies!I22) | AA22: =IFERROR(VLOOKUP(Z22,HurrDedTable,2,FALSE),1) | AB22: =IFERROR(INDEX(RateTables!$L$31:$L$33,MATCH(Policies!K22,RateTables!$K$31:$K$33,0)),1) | AC22: =ROUND(F22*D22*J22*AA22*AB22,2) | AD22: =MIN(AC22,Policies!G22*HurrCapPct) | AE22: =Y22+AD22 | AF22: =EDATE(Policies!M22,Policies!N22) | AG22: =ROUND(YEARFRAC(Policies!M22,AF22,3),4) | AH22: =ROUND(AE22*AG22,2) | AI22: =MAX(AH22,MinPremium) | AJ22: =ROUNDUP(AI22,0) | AK22: =VLOOKUP(Policies!N22,FeeTable,2,FALSE) | AL22: =ROUND(AJ22*AssessRate,2) | AM22: =ROUND((AJ22+AK22)*G22,2) | AN22: =AJ22+AK22+AL22+AM22 | AO22: =IF(OR(Policies!G22>1000000,C22>20,Policies!L22>=3),"REFER","OK") | AP22: =ROUND(AH22/D22,3) | AQ22: =Policies!B22&"-"&LEFT(Policies!C22,1)&TEXT(Policies!D22,"00")
A23: =Policies!A23 | B23: =IFERROR(DATEDIF(DATE(Policies!E23,1,1),Policies!M23,"y"),0) | C23: =Policies!F23*1 | D23: =Policies!G23/1000 | E23: =VLOOKUP(Policies!B23,BaseRates,2,FALSE) | F23: =VLOOKUP(Policies!B23,BaseRates,3,FALSE) | G23: =VLOOKUP(Policies!B23,BaseRates,4,FALSE) | H23: =ROUND(E23*D23,2) | I23: =INDEX(RateTables!$B$13:$B$16,MATCH(Policies!C23,RateTables!$A$13:$A$16,0)) | J23: =INDEX(RateTables!$C$13:$C$16,MATCH(Policies!C23,RateTables!$A$13:$A$16,0)) | K23: =INDEX(RateTables!$B$19:$C$28,MATCH(Policies!D23,RateTables!$A$19:$A$28,0),IF(Policies!C23="Frame",1,2)) | L23: =VLOOKUP(B23,AgeBands,2,TRUE) | M23: =VLOOKUP(C23,RoofBands,2,TRUE) | N23: =VLOOKUP(Policies!G23,AOIBands,2,TRUE) | O23: =VLOOKUP(Policies!H23,RateTables!$A$31:$B$35,2,TRUE) | P23: =VLOOKUP(MIN(Policies!L23,3),ClaimsTable,2,FALSE) | Q23: =ROUND(H23*I23*K23*L23*M23*N23*O23*P23,2) | R23: =IF(Policies!J23="Y",1,0) | S23: =IF(AND(Policies!L23=0,B23>=3),1,0) | T23: =IF(B23<=5,1,0) | U23: =IF(Policies!K23="Basic",1,0) | V23: =IF(Policies!K23="Fortified",1,0) | W23: =SUMPRODUCT(R23:V23,CreditPcts) | X23: =MIN(W23,CreditCap) | Y23: =ROUND(Q23*(1-X23),2) | Z23: =IF(Policies!I23="",0.02,Policies!I23) | AA23: =IFERROR(VLOOKUP(Z23,HurrDedTable,2,FALSE),1) | AB23: =IFERROR(INDEX(RateTables!$L$31:$L$33,MATCH(Policies!K23,RateTables!$K$31:$K$33,0)),1) | AC23: =ROUND(F23*D23*J23*AA23*AB23,2) | AD23: =MIN(AC23,Policies!G23*HurrCapPct) | AE23: =Y23+AD23 | AF23: =EDATE(Policies!M23,Policies!N23) | AG23: =ROUND(YEARFRAC(Policies!M23,AF23,3),4) | AH23: =ROUND(AE23*AG23,2) | AI23: =MAX(AH23,MinPremium) | AJ23: =ROUNDUP(AI23,0) | AK23: =VLOOKUP(Policies!N23,FeeTable,2,FALSE) | AL23: =ROUND(AJ23*AssessRate,2) | AM23: =ROUND((AJ23+AK23)*G23,2) | AN23: =AJ23+AK23+AL23+AM23 | AO23: =IF(OR(Policies!G23>1000000,C23>20,Policies!L23>=3),"REFER","OK") | AP23: =ROUND(AH23/D23,3) | AQ23: =Policies!B23&"-"&LEFT(Policies!C23,1)&TEXT(Policies!D23,"00")
A24: =Policies!A24 | B24: =IFERROR(DATEDIF(DATE(Policies!E24,1,1),Policies!M24,"y"),0) | C24: =Policies!F24*1 | D24: =Policies!G24/1000 | E24: =VLOOKUP(Policies!B24,BaseRates,2,FALSE) | F24: =VLOOKUP(Policies!B24,BaseRates,3,FALSE) | G24: =VLOOKUP(Policies!B24,BaseRates,4,FALSE) | H24: =ROUND(E24*D24,2) | I24: =INDEX(RateTables!$B$13:$B$16,MATCH(Policies!C24,RateTables!$A$13:$A$16,0)) | J24: =INDEX(RateTables!$C$13:$C$16,MATCH(Policies!C24,RateTables!$A$13:$A$16,0)) | K24: =INDEX(RateTables!$B$19:$C$28,MATCH(Policies!D24,RateTables!$A$19:$A$28,0),IF(Policies!C24="Frame",1,2)) | L24: =VLOOKUP(B24,AgeBands,2,TRUE) | M24: =VLOOKUP(C24,RoofBands,2,TRUE) | N24: =VLOOKUP(Policies!G24,AOIBands,2,TRUE) | O24: =VLOOKUP(Policies!H24,RateTables!$A$31:$B$35,2,TRUE) | P24: =VLOOKUP(MIN(Policies!L24,3),ClaimsTable,2,FALSE) | Q24: =ROUND(H24*I24*K24*L24*M24*N24*O24*P24,2) | R24: =IF(Policies!J24="Y",1,0) | S24: =IF(AND(Policies!L24=0,B24>=3),1,0) | T24: =IF(B24<=5,1,0) | U24: =IF(Policies!K24="Basic",1,0) | V24: =IF(Policies!K24="Fortified",1,0) | W24: =SUMPRODUCT(R24:V24,CreditPcts) | X24: =MIN(W24,CreditCap) | Y24: =ROUND(Q24*(1-X24),2) | Z24: =IF(Policies!I24="",0.02,Policies!I24) | AA24: =IFERROR(VLOOKUP(Z24,HurrDedTable,2,FALSE),1) | AB24: =IFERROR(INDEX(RateTables!$L$31:$L$33,MATCH(Policies!K24,RateTables!$K$31:$K$33,0)),1) | AC24: =ROUND(F24*D24*J24*AA24*AB24,2) | AD24: =MIN(AC24,Policies!G24*HurrCapPct) | AE24: =Y24+AD24 | AF24: =EDATE(Policies!M24,Policies!N24) | AG24: =ROUND(YEARFRAC(Policies!M24,AF24,3),4) | AH24: =ROUND(AE24*AG24,2) | AI24: =MAX(AH24,MinPremium) | AJ24: =ROUNDUP(AI24,0) | AK24: =VLOOKUP(Policies!N24,FeeTable,2,FALSE) | AL24: =ROUND(AJ24*AssessRate,2) | AM24: =ROUND((AJ24+AK24)*G24,2) | AN24: =AJ24+AK24+AL24+AM24 | AO24: =IF(OR(Policies!G24>1000000,C24>20,Policies!L24>=3),"REFER","OK") | AP24: =ROUND(AH24/D24,3) | AQ24: =Policies!B24&"-"&LEFT(Policies!C24,1)&TEXT(Policies!D24,"00")
A25: =Policies!A25 | B25: =IFERROR(DATEDIF(DATE(Policies!E25,1,1),Policies!M25,"y"),0) | C25: =Policies!F25*1 | D25: =Policies!G25/1000 | E25: =VLOOKUP(Policies!B25,BaseRates,2,FALSE) | F25: =VLOOKUP(Policies!B25,BaseRates,3,FALSE) | G25: =VLOOKUP(Policies!B25,BaseRates,4,FALSE) | H25: =ROUND(E25*D25,2) | I25: =INDEX(RateTables!$B$13:$B$16,MATCH(Policies!C25,RateTables!$A$13:$A$16,0)) | J25: =INDEX(RateTables!$C$13:$C$16,MATCH(Policies!C25,RateTables!$A$13:$A$16,0)) | K25: =INDEX(RateTables!$B$19:$C$28,MATCH(Policies!D25,RateTables!$A$19:$A$28,0),IF(Policies!C25="Frame",1,2)) | L25: =VLOOKUP(B25,AgeBands,2,TRUE) | M25: =VLOOKUP(C25,RoofBands,2,TRUE) | N25: =VLOOKUP(Policies!G25,AOIBands,2,TRUE) | O25: =VLOOKUP(Policies!H25,RateTables!$A$31:$B$35,2,TRUE) | P25: =VLOOKUP(MIN(Policies!L25,3),ClaimsTable,2,FALSE) | Q25: =ROUND(H25*I25*K25*L25*M25*N25*O25*P25,2) | R25: =IF(Policies!J25="Y",1,0) | S25: =IF(AND(Policies!L25=0,B25>=3),1,0) | T25: =IF(B25<=5,1,0) | U25: =IF(Policies!K25="Basic",1,0) | V25: =IF(Policies!K25="Fortified",1,0) | W25: =SUMPRODUCT(R25:V25,CreditPcts) | X25: =MIN(W25,CreditCap) | Y25: =ROUND(Q25*(1-X25),2) | Z25: =IF(Policies!I25="",0.02,Policies!I25) | AA25: =IFERROR(VLOOKUP(Z25,HurrDedTable,2,FALSE),1) | AB25: =IFERROR(INDEX(RateTables!$L$31:$L$33,MATCH(Policies!K25,RateTables!$K$31:$K$33,0)),1) | AC25: =ROUND(F25*D25*J25*AA25*AB25,2) | AD25: =MIN(AC25,Policies!G25*HurrCapPct) | AE25: =Y25+AD25 | AF25: =EDATE(Policies!M25,Policies!N25) | AG25: =ROUND(YEARFRAC(Policies!M25,AF25,3),4) | AH25: =ROUND(AE25*AG25,2) | AI25: =MAX(AH25,MinPremium) | AJ25: =ROUNDUP(AI25,0) | AK25: =VLOOKUP(Policies!N25,FeeTable,2,FALSE) | AL25: =ROUND(AJ25*AssessRate,2) | AM25: =ROUND((AJ25+AK25)*G25,2) | AN25: =AJ25+AK25+AL25+AM25 | AO25: =IF(OR(Policies!G25>1000000,C25>20,Policies!L25>=3),"REFER","OK") | AP25: =ROUND(AH25/D25,3) | AQ25: =Policies!B25&"-"&LEFT(Policies!C25,1)&TEXT(Policies!D25,"00")
A26: =Policies!A26 | B26: =IFERROR(DATEDIF(DATE(Policies!E26,1,1),Policies!M26,"y"),0) | C26: =Policies!F26*1 | D26: =Policies!G26/1000 | E26: =VLOOKUP(Policies!B26,BaseRates,2,FALSE) | F26: =VLOOKUP(Policies!B26,BaseRates,3,FALSE) | G26: =VLOOKUP(Policies!B26,BaseRates,4,FALSE) | H26: =ROUND(E26*D26,2) | I26: =INDEX(RateTables!$B$13:$B$16,MATCH(Policies!C26,RateTables!$A$13:$A$16,0)) | J26: =INDEX(RateTables!$C$13:$C$16,MATCH(Policies!C26,RateTables!$A$13:$A$16,0)) | K26: =INDEX(RateTables!$B$19:$C$28,MATCH(Policies!D26,RateTables!$A$19:$A$28,0),IF(Policies!C26="Frame",1,2)) | L26: =VLOOKUP(B26,AgeBands,2,TRUE) | M26: =VLOOKUP(C26,RoofBands,2,TRUE) | N26: =VLOOKUP(Policies!G26,AOIBands,2,TRUE) | O26: =VLOOKUP(Policies!H26,RateTables!$A$31:$B$35,2,TRUE) | P26: =VLOOKUP(MIN(Policies!L26,3),ClaimsTable,2,FALSE) | Q26: =ROUND(H26*I26*K26*L26*M26*N26*O26*P26,2) | R26: =IF(Policies!J26="Y",1,0) | S26: =IF(AND(Policies!L26=0,B26>=3),1,0) | T26: =IF(B26<=5,1,0) | U26: =IF(Policies!K26="Basic",1,0) | V26: =IF(Policies!K26="Fortified",1,0) | W26: =SUMPRODUCT(R26:V26,CreditPcts) | X26: =MIN(W26,CreditCap) | Y26: =ROUND(Q26*(1-X26),2) | Z26: =IF(Policies!I26="",0.02,Policies!I26) | AA26: =IFERROR(VLOOKUP(Z26,HurrDedTable,2,FALSE),1) | AB26: =IFERROR(INDEX(RateTables!$L$31:$L$33,MATCH(Policies!K26,RateTables!$K$31:$K$33,0)),1) | AC26: =ROUND(F26*D26*J26*AA26*AB26,2) | AD26: =MIN(AC26,Policies!G26*HurrCapPct) | AE26: =Y26+AD26 | AF26: =EDATE(Policies!M26,Policies!N26) | AG26: =ROUND(YEARFRAC(Policies!M26,AF26,3),4) | AH26: =ROUND(AE26*AG26,2) | AI26: =MAX(AH26,MinPremium) | AJ26: =ROUNDUP(AI26,0) | AK26: =VLOOKUP(Policies!N26,FeeTable,2,FALSE) | AL26: =ROUND(AJ26*AssessRate,2) | AM26: =ROUND((AJ26+AK26)*G26,2) | AN26: =AJ26+AK26+AL26+AM26 | AO26: =IF(OR(Policies!G26>1000000,C26>20,Policies!L26>=3),"REFER","OK") | AP26: =ROUND(AH26/D26,3) | AQ26: =Policies!B26&"-"&LEFT(Policies!C26,1)&TEXT(Policies!D26,"00")
A27: =Policies!A27 | B27: =IFERROR(DATEDIF(DATE(Policies!E27,1,1),Policies!M27,"y"),0) | C27: =Policies!F27*1 | D27: =Policies!G27/1000 | E27: =VLOOKUP(Policies!B27,BaseRates,2,FALSE) | F27: =VLOOKUP(Policies!B27,BaseRates,3,FALSE) | G27: =VLOOKUP(Policies!B27,BaseRates,4,FALSE) | H27: =ROUND(E27*D27,2) | I27: =INDEX(RateTables!$B$13:$B$16,MATCH(Policies!C27,RateTables!$A$13:$A$16,0)) | J27: =INDEX(RateTables!$C$13:$C$16,MATCH(Policies!C27,RateTables!$A$13:$A$16,0)) | K27: =INDEX(RateTables!$B$19:$C$28,MATCH(Policies!D27,RateTables!$A$19:$A$28,0),IF(Policies!C27="Frame",1,2)) | L27: =VLOOKUP(B27,AgeBands,2,TRUE) | M27: =VLOOKUP(C27,RoofBands,2,TRUE) | N27: =VLOOKUP(Policies!G27,AOIBands,2,TRUE) | O27: =VLOOKUP(Policies!H27,RateTables!$A$31:$B$35,2,TRUE) | P27: =VLOOKUP(MIN(Policies!L27,3),ClaimsTable,2,FALSE) | Q27: =ROUND(H27*I27*K27*L27*M27*N27*O27*P27,2) | R27: =IF(Policies!J27="Y",1,0) | S27: =IF(AND(Policies!L27=0,B27>=3),1,0) | T27: =IF(B27<=5,1,0) | U27: =IF(Policies!K27="Basic",1,0) | V27: =IF(Policies!K27="Fortified",1,0) | W27: =SUMPRODUCT(R27:V27,CreditPcts) | X27: =MIN(W27,CreditCap) | Y27: =ROUND(Q27*(1-X27),2) | Z27: =IF(Policies!I27="",0.02,Policies!I27) | AA27: =IFERROR(VLOOKUP(Z27,HurrDedTable,2,FALSE),1) | AB27: =IFERROR(INDEX(RateTables!$L$31:$L$33,MATCH(Policies!K27,RateTables!$K$31:$K$33,0)),1) | AC27: =ROUND(F27*D27*J27*AA27*AB27,2) | AD27: =MIN(AC27,Policies!G27*HurrCapPct) | AE27: =Y27+AD27 | AF27: =EDATE(Policies!M27,Policies!N27) | AG27: =ROUND(YEARFRAC(Policies!M27,AF27,3),4) | AH27: =ROUND(AE27*AG27,2) | AI27: =MAX(AH27,MinPremium) | AJ27: =ROUNDUP(AI27,0) | AK27: =VLOOKUP(Policies!N27,FeeTable,2,FALSE) | AL27: =ROUND(AJ27*AssessRate,2) | AM27: =ROUND((AJ27+AK27)*G27,2) | AN27: =AJ27+AK27+AL27+AM27 | AO27: =IF(OR(Policies!G27>1000000,C27>20,Policies!L27>=3),"REFER","OK") | AP27: =ROUND(AH27/D27,3) | AQ27: =Policies!B27&"-"&LEFT(Policies!C27,1)&TEXT(Policies!D27,"00")
A28: =Policies!A28 | B28: =IFERROR(DATEDIF(DATE(Policies!E28,1,1),Policies!M28,"y"),0) | C28: =Policies!F28*1 | D28: =Policies!G28/1000 | E28: =VLOOKUP(Policies!B28,BaseRates,2,FALSE) | F28: =VLOOKUP(Policies!B28,BaseRates,3,FALSE) | G28: =VLOOKUP(Policies!B28,BaseRates,4,FALSE) | H28: =ROUND(E28*D28,2) | I28: =INDEX(RateTables!$B$13:$B$16,MATCH(Policies!C28,RateTables!$A$13:$A$16,0)) | J28: =INDEX(RateTables!$C$13:$C$16,MATCH(Policies!C28,RateTables!$A$13:$A$16,0)) | K28: =INDEX(RateTables!$B$19:$C$28,MATCH(Policies!D28,RateTables!$A$19:$A$28,0),IF(Policies!C28="Frame",1,2)) | L28: =VLOOKUP(B28,AgeBands,2,TRUE) | M28: =VLOOKUP(C28,RoofBands,2,TRUE) | N28: =VLOOKUP(Policies!G28,AOIBands,2,TRUE) | O28: =VLOOKUP(Policies!H28,RateTables!$A$31:$B$35,2,TRUE) | P28: =VLOOKUP(MIN(Policies!L28,3),ClaimsTable,2,FALSE) | Q28: =ROUND(H28*I28*K28*L28*M28*N28*O28*P28,2) | R28: =IF(Policies!J28="Y",1,0) | S28: =IF(AND(Policies!L28=0,B28>=3),1,0) | T28: =IF(B28<=5,1,0) | U28: =IF(Policies!K28="Basic",1,0) | V28: =IF(Policies!K28="Fortified",1,0) | W28: =SUMPRODUCT(R28:V28,CreditPcts) | X28: =MIN(W28,CreditCap) | Y28: =ROUND(Q28*(1-X28),2) | Z28: =IF(Policies!I28="",0.02,Policies!I28) | AA28: =IFERROR(VLOOKUP(Z28,HurrDedTable,2,FALSE),1) | AB28: =IFERROR(INDEX(RateTables!$L$31:$L$33,MATCH(Policies!K28,RateTables!$K$31:$K$33,0)),1) | AC28: =ROUND(F28*D28*J28*AA28*AB28,2) | AD28: =MIN(AC28,Policies!G28*HurrCapPct) | AE28: =Y28+AD28 | AF28: =EDATE(Policies!M28,Policies!N28) | AG28: =ROUND(YEARFRAC(Policies!M28,AF28,3),4) | AH28: =ROUND(AE28*AG28,2) | AI28: =MAX(AH28,MinPremium) | AJ28: =ROUNDUP(AI28,0) | AK28: =VLOOKUP(Policies!N28,FeeTable,2,FALSE) | AL28: =ROUND(AJ28*AssessRate,2) | AM28: =ROUND((AJ28+AK28)*G28,2) | AN28: =AJ28+AK28+AL28+AM28 | AO28: =IF(OR(Policies!G28>1000000,C28>20,Policies!L28>=3),"REFER","OK") | AP28: =ROUND(AH28/D28,3) | AQ28: =Policies!B28&"-"&LEFT(Policies!C28,1)&TEXT(Policies!D28,"00")
A29: =Policies!A29 | B29: =IFERROR(DATEDIF(DATE(Policies!E29,1,1),Policies!M29,"y"),0) | C29: =Policies!F29*1 | D29: =Policies!G29/1000 | E29: =VLOOKUP(Policies!B29,BaseRates,2,FALSE) | F29: =VLOOKUP(Policies!B29,BaseRates,3,FALSE) | G29: =VLOOKUP(Policies!B29,BaseRates,4,FALSE) | H29: =ROUND(E29*D29,2) | I29: =INDEX(RateTables!$B$13:$B$16,MATCH(Policies!C29,RateTables!$A$13:$A$16,0)) | J29: =INDEX(RateTables!$C$13:$C$16,MATCH(Policies!C29,RateTables!$A$13:$A$16,0)) | K29: =INDEX(RateTables!$B$19:$C$28,MATCH(Policies!D29,RateTables!$A$19:$A$28,0),IF(Policies!C29="Frame",1,2)) | L29: =VLOOKUP(B29,AgeBands,2,TRUE) | M29: =VLOOKUP(C29,RoofBands,2,TRUE) | N29: =VLOOKUP(Policies!G29,AOIBands,2,TRUE) | O29: =VLOOKUP(Policies!H29,RateTables!$A$31:$B$35,2,TRUE) | P29: =VLOOKUP(MIN(Policies!L29,3),ClaimsTable,2,FALSE) | Q29: =ROUND(H29*I29*K29*L29*M29*N29*O29*P29,2) | R29: =IF(Policies!J29="Y",1,0) | S29: =IF(AND(Policies!L29=0,B29>=3),1,0) | T29: =IF(B29<=5,1,0) | U29: =IF(Policies!K29="Basic",1,0) | V29: =IF(Policies!K29="Fortified",1,0) | W29: =SUMPRODUCT(R29:V29,CreditPcts) | X29: =MIN(W29,CreditCap) | Y29: =ROUND(Q29*(1-X29),2) | Z29: =IF(Policies!I29="",0.02,Policies!I29) | AA29: =IFERROR(VLOOKUP(Z29,HurrDedTable,2,FALSE),1) | AB29: =IFERROR(INDEX(RateTables!$L$31:$L$33,MATCH(Policies!K29,RateTables!$K$31:$K$33,0)),1) | AC29: =ROUND(F29*D29*J29*AA29*AB29,2) | AD29: =MIN(AC29,Policies!G29*HurrCapPct) | AE29: =Y29+AD29 | AF29: =EDATE(Policies!M29,Policies!N29) | AG29: =ROUND(YEARFRAC(Policies!M29,AF29,3),4) | AH29: =ROUND(AE29*AG29,2) | AI29: =MAX(AH29,MinPremium) | AJ29: =ROUNDUP(AI29,0) | AK29: =VLOOKUP(Policies!N29,FeeTable,2,FALSE) | AL29: =ROUND(AJ29*AssessRate,2) | AM29: =ROUND((AJ29+AK29)*G29,2) | AN29: =AJ29+AK29+AL29+AM29 | AO29: =IF(OR(Policies!G29>1000000,C29>20,Policies!L29>=3),"REFER","OK") | AP29: =ROUND(AH29/D29,3) | AQ29: =Policies!B29&"-"&LEFT(Policies!C29,1)&TEXT(Policies!D29,"00")
